Workbook

Sheet 1_Dashboard
A1: TABLERO INSTITUCIONAL BTC / ETH — DASHBOARD OPERATIVO v3
A2: v3: motor de liquidaciones ampliado. Valores de respaldo del 28-ago-2026: se sustituyen al refrescar (Datos > Actualizar todo).
A4: A. ESTADO EN VIVO
A5: Metrica | B5: Valor en vivo | C5: Fuente | D5: Manual (respaldo) | E5: EN USO | F5: Unidad | G5: Lectura | H5: Comentario
A6: Precio BTC (spot) | B6: =IF(ISNUMBER('2_Live_Precios'!G5),'2_Live_Precios'!G5,IF(COUNT('12_Datos_5m'!$F$5:$F$504)>0,INDEX('12_Datos_5m'!$F$5:$F$504,COUNT('12_Datos_5m'!$F$5:$F$504)),"n/d")) -> n/d | C6: Binance / 5m | D6: 77477 | E6: =IF(ISNUMBER(B6),B6,D6) -> 77477 | F6: USD | G6: =IF(NOT(ISNUMBER(E6)),"—",IF(E6>=$B$33,"ALCISTA",IF(E6>=$B$34,"NEUTRO-ALCISTA",IF(E6>=$B$35,"BISAGRA",IF(E6>=$B$36,"NEUTRO-BAJISTA",IF(E6>=$B$37,"ZONA SPRING","QUIEBRE")))))) -> BISAGRA | H6: Ultimo dato citado 28-ago: 77,477
A7: Precio ETH (spot) | B7: =IFERROR(IF(ISNUMBER('2_Live_Precios'!G6),'2_Live_Precios'!G6,"n/d"),"n/d") -> n/d | C7: Binance | D7: 2501 | E7: =IF(ISNUMBER(B7),B7,D7) -> 2501 | F7: USD | G7: =IF(NOT(ISNUMBER(E7)),"—",IF(E7>=2534,"SOBRE EMA200-3D",IF(E7>=2503,"SOBRE PIVOTE",IF(E7>=2471,"PIVOTE PERDIDO",IF(E7>=2426,"ZONA SPRING","VACIO <2400"))))) -> PIVOTE PERDIDO | H7: EMA200(3D) ~2,534 / pivote 2,503
A8: Funding BTC perp (8h) | B8: =IFERROR(IF(ISNUMBER('3_Live_Derivados'!G5),'3_Live_Derivados'!G5,"n/d"),"n/d") -> n/d | C8: Binance F. | D8: 4.8e-05 | E8: =IF(ISNUMBER(B8),B8,D8) -> 4.8e-05 | F8: frac | G8: =IF(NOT(ISNUMBER(E8)),"—",IF(E8>0.0003,"SOBRECALENTADO",IF(E8>0.0001,"POSITIVO",IF(E8>=-0.0001,"NEUTRO","NEGATIVO")))) -> NEUTRO | H8: Neutro = combustible alcista limpio
A9: Open Interest BTC (USD) | B9: =IFERROR(IF(ISNUMBER('3_Live_Derivados'!G7),'3_Live_Derivados'!G7*E6,"n/d"),"n/d") -> n/d | C9: Binance F. | D9: 56480000000 | E9: =IF(ISNUMBER(B9),B9,D9) -> 56480000000 | F9: USD | G9: =IF(NOT(ISNUMBER(E9)),"—",IF(E9>60000000000,"APALANCAMIENTO ALTO",IF(E9>45000000000,"NORMAL","DESAPALANCADO"))) -> NORMAL | H9: Solo Binance en vivo; manual = agregado 56.48B
A10: Long/Short cuentas BTC | B10: =IFERROR(IF(ISNUMBER('3_Live_Derivados'!G9),'3_Live_Derivados'!G9,"n/d"),"n/d") -> n/d | C10: Binance F. | D10: 1.98 | E10: =IF(ISNUMBER(B10),B10,D10) -> 1.98 | F10: ratio | G10: =IF(NOT(ISNUMBER(E10)),"—",IF(E10>2.2,"RETAIL MUY LARGO",IF(E10>1.6,"RETAIL LARGO",IF(E10>1.1,"EQUILIBRIO","RETAIL CORTO")))) -> RETAIL LARGO | H10: Retail. >2 = combustible bajista
A11: Long/Short top traders | B11: =IFERROR(IF(ISNUMBER('3_Live_Derivados'!G10),'3_Live_Derivados'!G10,"n/d"),"n/d") -> n/d | C11: Binance F. | D11: 1.35 | E11: =IF(ISNUMBER(B11),B11,D11) -> 1.35 | F11: ratio | G11: =IF(OR(NOT(ISNUMBER(E11)),NOT(ISNUMBER(E10))),"—",IF(E10-E11>0.5,"DIVERGENCIA FUERTE",IF(E10-E11>0.2,"DIVERGENCIA","ALINEADOS"))) -> DIVERGENCIA FUERTE | H11: Divergencia retail vs pro = seccion 2.5
A12: Fear & Greed | B12: =IFERROR(IF(ISNUMBER('4_Live_Macro'!G5),'4_Live_Macro'!G5,"n/d"),"n/d") -> n/d | C12: alternative.me | D12: 62 | E12: =IF(ISNUMBER(B12),B12,D12) -> 62 | F12: 0-100 | G12: =IF(NOT(ISNUMBER(E12)),"—",IF(E12>=75,"CODICIA EXTREMA",IF(E12>=55,"CODICIA",IF(E12>=45,"NEUTRO",IF(E12>=25,"MIEDO","MIEDO EXTREMO"))))) -> CODICIA | H12: Sentimiento agregado
A13: Rend. Tesoro 2A (%) | B13: =IFERROR(IF(ISNUMBER('4_Live_Macro'!G11),'4_Live_Macro'!G11,"n/d"),"n/d") -> n/d | C13: Tesoro EEUU | D13: 4.35 | E13: =IF(ISNUMBER(B13),B13,D13) -> 4.35 | F13: % | G13: =IF(NOT(ISNUMBER(E13)),"—",IF(E13>4.5,"RESTRICTIVO",IF(E13>4.2,"TENSION","ALIVIO"))) -> TENSION | H13: 28-ago: +12pb a 4.35%
A15: B. VEREDICTO — PROBABILIDADES (motor en hoja 6)
A16: Escenario | B16: Prob. base | C16: Ajuste en vivo | D16: PROB. FINAL | E16: Disparador | F16: Objetivo BTC | G16: Objetivo ETH | H16: Accion
A17: FALSA CAIDA (barrida y vuelta) | B17: 0.45 | C17: =IF(AND(ISNUMBER($E$10),$E$10>2),0.05,0) -> 0 | D17: =MAX(0,B17+C17)/(MAX(0,B17+C17)+MAX(0,B18+C18)+MAX(0,B19+C19)) -> 0.44117647 | E17: Perder 76,900 con volumen | F17: 74,000–76,500 | G17: 2,400–2,463 | H17: Esperar cascada >800M/h y comprar
A18: ABURRIMIENTO (rango) | B18: 0.28 | C18: =IF(AND(ISNUMBER($E$6),$E$6>=77250,$E$6<=79000),0.05,-0.02) -> 0.05 | D18: =MAX(0,B18+C18)/(MAX(0,B17+C17)+MAX(0,B18+C18)+MAX(0,B19+C19)) -> 0.32352941 | E18: Cierre semanal 77.25K–79K | F18: 76,900–80,000 | G18: 2,463–2,528 | H18: No operar; esperar ETF del lunes
A19: SUBIDA VIOLENTA (squeeze) | B19: 0.27 | C19: =IF(AND(ISNUMBER($E$6),$E$6>79000),0.08,-0.03) -> -0.03 | D19: =MAX(0,B19+C19)/(MAX(0,B17+C17)+MAX(0,B18+C18)+MAX(0,B19+C19)) -> 0.23529412 | E19: Cierre 4H >79,000 con OI al alza | F19: 81,033 → 82,400 | G19: 2,528 → 2,600 | H19: Perseguir largo con stop bajo 79,000
A20: ESCENARIO DOMINANTE | B20: =INDEX(A17:A19,MATCH(MAX(D17:D19),D17:D19,0)) -> FALSA CAIDA (barrida y vuelta) | F20: =MAX(D17:D19) -> 0.44117647 | G20: confianza
A22: C. SEMAFORO DE ENTRADA — 5 FILTROS DE ARBITRAJE POST-LIQUIDACION
A23: Filtro | B23: Umbral | C23: Valor actual | D23: Cumple | E23: Peso | F23: Puntos | G23: Fuente del dato | H23: Nota
A24: 1. Liquidaciones 1h | B24: >= 800 M USD | C24: =IF(N('5_Liquidaciones'!C7)>0,'5_Liquidaciones'!C7,'15_Liq_Reales'!D12+'15_Liq_Reales'!D13) -> 0 | D24: =IF(NOT(ISNUMBER(C24)),0,IF(C24>=800000000,1,0)) -> 0 | E24: 1 | F24: =D24*E24 -> 0 | G24: Coinglass manual > reales | H24: El tamano del rebote escala con esto
A25: 2. % del OI purgado | B25: >= 2.5% | C25: =IF(ISNUMBER('16_Fase_Cascada'!B14),'16_Fase_Cascada'!B14,'5_Liquidaciones'!C17) -> 0.0086345609 | D25: =IF(NOT(ISNUMBER(C25)),0,IF(C25>=0.025,1,0)) -> 0 | E25: 1.5 | F25: =D25*E25 -> 0 | G25: Hoja 16 > manual | H25: 0.86% hoy = purga incompleta
A26: 3. Dominancia de longs | B26: >= 75% | C26: =IF(ISNUMBER('15_Liq_Reales'!D18),'15_Liq_Reales'!D18,'5_Liquidaciones'!C16) -> 0.73818898 | D26: =IF(NOT(ISNUMBER(C26)),0,IF(C26>=0.75,1,0)) -> 0 | E26: 1 | F26: =D26*E26 -> 0 | G26: Hoja 15 > manual | H26: 74% hoy
A27: 4. Funding pre-caida | B27: <= 0.0100% | C27: =$E$8 -> 4.8e-05 | D27: =IF(NOT(ISNUMBER(C27)),0,IF(C27<=0.0001,1,0)) -> 1 | E27: 1 | F27: =D27*E27 -> 1 | G27: Binance API | H27: Neutro o negativo
A28: 5. Bid spot (ETF) | B28: Flujos positivos | C28: ='5_Liquidaciones'!C12 -> 1 | D28: =IF(NOT(ISNUMBER(C28)),0,IF(C28>=0.5,1,0)) -> 1 | E28: 0.5 | F28: =D28*E28 -> 0.5 | G28: Farside / manual | H28: 1 = si, 0 = no
A29: PUNTUACION TOTAL | B29: =SUM(F24:F28) -> 1.5 | C29: de 5.0 | D29: =IF(B29>=4,"ENTRAR",IF(B29>=3,"PREPARAR ORDEN","NO OPERAR")) -> NO OPERAR | G29: Regla: 4 de 5 filtros minimo
A31: D. MAPA DE NIVELES — DISTANCIA AL PRECIO EN VIVO
A32: Nivel BTC | B32: Precio | C32: Distancia % | D32: Tipo | E32: Significado | F32: Nivel ETH | G32: Precio | H32: Distancia % | I32: Tipo
A33: MA 50 semanas | B33: 81033 | C33: =IF(ISNUMBER($E$6),($E$6-B33)/B33,"n/d") -> -0.043883356 | D33: Resistencia mayor | E33: Sobre esto muere la tesis bajista | F33: EMA 200 (3D) | G33: 2534 | H33: =IF(ISNUMBER($E$7),($E$7-G33)/G33,"n/d") -> -0.013022889 | I33: Techo del rally
A34: Gatillo squeeze | B34: 79000 | C34: =IF(ISNUMBER($E$6),($E$6-B34)/B34,"n/d") -> -0.019278481 | D34: Disparador alcista | E34: Cierre 4H encima = plan B | F34: Pivote diario | G34: 2503 | H34: =IF(ISNUMBER($E$7),($E$7-G34)/G34,"n/d") -> -0.00079904115 | I34: El arbitro
A35: EMA 50 semanas | B35: 77250 | C35: =IF(ISNUMBER($E$6),($E$6-B35)/B35,"n/d") -> 0.0029385113 | D35: BISAGRA DEL CICLO | E35: Define tendencia mayor | F35: Soporte diario | G35: 2471 | H35: =IF(ISNUMBER($E$7),($E$7-G35)/G35,"n/d") -> 0.012140834 | I35: Perderlo gira bajista
A36: Minimo 28-ago | B36: 76909 | C36: =IF(ISNUMBER($E$6),($E$6-B36)/B36,"n/d") -> 0.0073853515 | D36: Soporte probado | E36: Separa falsa caida de caida real | F36: Zona Spring | G36: 2426 | H36: =IF(ISNUMBER($E$7),($E$7-G36)/G36,"n/d") -> 0.030915087 | I36: Soporte 5-10 dias
A37: Bolsa de liquidez | B37: 74000 | C37: =IF(ISNUMBER($E$6),($E$6-B37)/B37,"n/d") -> 0.046986486 | D37: Zona Spring | E37: Objetivo de barrida | F37: Ultima red | G37: 2400 | H37: =IF(ISNUMBER($E$7),($E$7-G37)/G37,"n/d") -> 0.042083333 | I37: Debajo: vacio a 2,250
A38: Quiebre estructural | B38: 73800 | C38: =IF(ISNUMBER($E$6),($E$6-B38)/B38,"n/d") -> 0.049823848 | D38: Invalidacion | E38: Debajo = distribucion confirmada | F38: Cluster mayor | G38: 2250 | H38: =IF(ISNUMBER($E$7),($E$7-G38)/G38,"n/d") -> 0.11155556 | I38: Siguiente liquidez
A40: F. LIQUIDACIONES EN VIVO — mapa estimado, prints reales y fase del ciclo
A41: Indicador | B41: Valor | E41: Lectura / contexto | H41: Hoja
A42: FASE DEL CICLO DE LIQUIDACION | B42: ='16_Fase_Cascada'!B28 -> SIN DATOS SUFICIENTES | E42: ='16_Fase_Cascada'!B29 -> Instala y refresca qBase5m (hoja 9). | H42: 16
A43: Cuadrante precio/OI 1h | B43: ='16_Fase_Cascada'!C12 -> n/d | E43: ="4h: "&'16_Fase_Cascada'!D12 -> 4h: n/d | H43: 16
A44: Purga de OI desde maximo 24h | B44: ='16_Fase_Cascada'!B14 -> n/d | E44: ="Umbral de limpieza: 2.5%" -> Umbral de limpieza: 2.5% | H44: 16
A45: Primer cluster LONG (precio) | B45: ='13_Mapa_Liq'!B32 -> n/d | E45: =IF(ISNUMBER('13_Mapa_Liq'!B33),"a "&ROUND('13_Mapa_Liq'!B33*100,1)&"% del precio","sin datos") -> sin datos | H45: 13
...

Sheet 2_Live_Precios
A1: PRECIOS EN VIVO — APIs PUBLICAS SIN CLAVE
A2: Redundancia deliberada: cuatro fuentes independientes para el mismo precio. Si divergen mas de 0.3%, hay estres de liquidez.
A3: La columna E llama a la API. La F aisla el fragmento. La G convierte a numero. Si ves SIN CONEXION, habilita el acceso a datos externos o usa Power Query (hoja 9).
A4: Indicador | B4: Fuente | C4: URL del endpoint (publico, sin clave) | D4: Clave JSON | E4: Respuesta cruda (WEBSERVICE) | F4: Fragmento aislado | G4: VALOR | H4: Unidad | I4: Como se usa en el modelo
A5: BTC spot (Binance) | B5: Binance | C5: https://api.binance.com/api/v3/ticker/price?symbol=BTCUSDT | D5: price | E5: =IFERROR(webservice(C5),"SIN CONEXION") -> SIN CONEXION | F5: =IFERROR(MID(E5,SEARCH(""""&D5&""":",E5)+LEN(D5)+3,32),"n/d") -> n/d | G5: =IFERROR(VALUE(SUBSTITUTE(LEFT(SUBSTITUTE(SUBSTITUTE(F5,"""",""),"[",""),MIN(IFERROR(SEARCH(",",SUBSTITUTE(SUBSTITUTE(F5,"""",""),"[","")),99),IFERROR(SEARCH("}",SUBSTITUTE(SUBSTITUTE(F5,"""",""),"[","")),99),IFERROR(SEARCH("]",SUBSTITUTE(SUBSTITUTE(F5,"""",""),"[","")),99))-1),".",MID(1/2,2,1))),"n/d") -> n/d | H5: USD | I5: Precio principal del modelo. Alimenta E6 del dashboard.
A6: ETH spot (Binance) | B6: Binance | C6: https://api.binance.com/api/v3/ticker/price?symbol=ETHUSDT | D6: price | E6: =IFERROR(webservice(C6),"SIN CONEXION") -> SIN CONEXION | F6: =IFERROR(MID(E6,SEARCH(""""&D6&""":",E6)+LEN(D6)+3,32),"n/d") -> n/d | G6: =IFERROR(VALUE(SUBSTITUTE(LEFT(SUBSTITUTE(SUBSTITUTE(F6,"""",""),"[",""),MIN(IFERROR(SEARCH(",",SUBSTITUTE(SUBSTITUTE(F6,"""",""),"[","")),99),IFERROR(SEARCH("}",SUBSTITUTE(SUBSTITUTE(F6,"""",""),"[","")),99),IFERROR(SEARCH("]",SUBSTITUTE(SUBSTITUTE(F6,"""",""),"[","")),99))-1),".",MID(1/2,2,1))),"n/d") -> n/d | H6: USD | I6: Precio ETH. Alimenta E7 del dashboard.
A7: BTC var. 24h | B7: Binance | C7: https://api.binance.com/api/v3/ticker/24hr?symbol=BTCUSDT | D7: priceChangePercent | E7: =IFERROR(webservice(C7),"SIN CONEXION") -> SIN CONEXION | F7: =IFERROR(MID(E7,SEARCH(""""&D7&""":",E7)+LEN(D7)+3,32),"n/d") -> n/d | G7: =IFERROR(VALUE(SUBSTITUTE(LEFT(SUBSTITUTE(SUBSTITUTE(F7,"""",""),"[",""),MIN(IFERROR(SEARCH(",",SUBSTITUTE(SUBSTITUTE(F7,"""",""),"[","")),99),IFERROR(SEARCH("}",SUBSTITUTE(SUBSTITUTE(F7,"""",""),"[","")),99),IFERROR(SEARCH("]",SUBSTITUTE(SUBSTITUTE(F7,"""",""),"[","")),99))-1),".",MID(1/2,2,1))),"n/d") -> n/d | H7: % | I7: Magnitud del movimiento diario. -4% hoy.
A8: BTC minimo 24h | B8: Binance | C8: https://api.binance.com/api/v3/ticker/24hr?symbol=BTCUSDT | D8: lowPrice | E8: =IFERROR(webservice(C8),"SIN CONEXION") -> SIN CONEXION | F8: =IFERROR(MID(E8,SEARCH(""""&D8&""":",E8)+LEN(D8)+3,32),"n/d") -> n/d | G8: =IFERROR(VALUE(SUBSTITUTE(LEFT(SUBSTITUTE(SUBSTITUTE(F8,"""",""),"[",""),MIN(IFERROR(SEARCH(",",SUBSTITUTE(SUBSTITUTE(F8,"""",""),"[","")),99),IFERROR(SEARCH("}",SUBSTITUTE(SUBSTITUTE(F8,"""",""),"[","")),99),IFERROR(SEARCH("]",SUBSTITUTE(SUBSTITUTE(F8,"""",""),"[","")),99))-1),".",MID(1/2,2,1))),"n/d") -> n/d | H8: USD | I8: Cola de la mecha. Compara con la zona de captura.
A9: BTC maximo 24h | B9: Binance | C9: https://api.binance.com/api/v3/ticker/24hr?symbol=BTCUSDT | D9: highPrice | E9: =IFERROR(webservice(C9),"SIN CONEXION") -> SIN CONEXION | F9: =IFERROR(MID(E9,SEARCH(""""&D9&""":",E9)+LEN(D9)+3,32),"n/d") -> n/d | G9: =IFERROR(VALUE(SUBSTITUTE(LEFT(SUBSTITUTE(SUBSTITUTE(F9,"""",""),"[",""),MIN(IFERROR(SEARCH(",",SUBSTITUTE(SUBSTITUTE(F9,"""",""),"[","")),99),IFERROR(SEARCH("}",SUBSTITUTE(SUBSTITUTE(F9,"""",""),"[","")),99),IFERROR(SEARCH("]",SUBSTITUTE(SUBSTITUTE(F9,"""",""),"[","")),99))-1),".",MID(1/2,2,1))),"n/d") -> n/d | H9: USD | I9: Rango del dia = ATR intradia aproximado.
A10: BTC volumen 24h (quote) | B10: Binance | C10: https://api.binance.com/api/v3/ticker/24hr?symbol=BTCUSDT | D10: quoteVolume | E10: =IFERROR(webservice(C10),"SIN CONEXION") -> SIN CONEXION | F10: =IFERROR(MID(E10,SEARCH(""""&D10&""":",E10)+LEN(D10)+3,32),"n/d") -> n/d | G10: =IFERROR(VALUE(SUBSTITUTE(LEFT(SUBSTITUTE(SUBSTITUTE(F10,"""",""),"[",""),MIN(IFERROR(SEARCH(",",SUBSTITUTE(SUBSTITUTE(F10,"""",""),"[","")),99),IFERROR(SEARCH("}",SUBSTITUTE(SUBSTITUTE(F10,"""",""),"[","")),99),IFERROR(SEARCH("]",SUBSTITUTE(SUBSTITUTE(F10,"""",""),"[","")),99))-1),".",MID(1/2,2,1))),"n/d") -> n/d | H10: USD | I10: Volumen spot. Si sube en la caida, la venta es real.
A11: ETH var. 24h | B11: Binance | C11: https://api.binance.com/api/v3/ticker/24hr?symbol=ETHUSDT | D11: priceChangePercent | E11: =IFERROR(webservice(C11),"SIN CONEXION") -> SIN CONEXION | F11: =IFERROR(MID(E11,SEARCH(""""&D11&""":",E11)+LEN(D11)+3,32),"n/d") -> n/d | G11: =IFERROR(VALUE(SUBSTITUTE(LEFT(SUBSTITUTE(SUBSTITUTE(F11,"""",""),"[",""),MIN(IFERROR(SEARCH(",",SUBSTITUTE(SUBSTITUTE(F11,"""",""),"[","")),99),IFERROR(SEARCH("}",SUBSTITUTE(SUBSTITUTE(F11,"""",""),"[","")),99),IFERROR(SEARCH("]",SUBSTITUTE(SUBSTITUTE(F11,"""",""),"[","")),99))-1),".",MID(1/2,2,1))),"n/d") -> n/d | H11: % | I11: Beta de ETH vs BTC = fila 3 dividida por esta.
A12: ETH minimo 24h | B12: Binance | C12: https://api.binance.com/api/v3/ticker/24hr?symbol=ETHUSDT | D12: lowPrice | E12: =IFERROR(webservice(C12),"SIN CONEXION") -> SIN CONEXION | F12: =IFERROR(MID(E12,SEARCH(""""&D12&""":",E12)+LEN(D12)+3,32),"n/d") -> n/d | G12: =IFERROR(VALUE(SUBSTITUTE(LEFT(SUBSTITUTE(SUBSTITUTE(F12,"""",""),"[",""),MIN(IFERROR(SEARCH(",",SUBSTITUTE(SUBSTITUTE(F12,"""",""),"[","")),99),IFERROR(SEARCH("}",SUBSTITUTE(SUBSTITUTE(F12,"""",""),"[","")),99),IFERROR(SEARCH("]",SUBSTITUTE(SUBSTITUTE(F12,"""",""),"[","")),99))-1),".",MID(1/2,2,1))),"n/d") -> n/d | H12: USD | I12: Compara con 2,426 y 2,400.
A13: BTC spot (Coinbase) | B13: Coinbase | C13: https://api.coinbase.com/v2/prices/BTC-USD/spot | D13: amount | E13: =IFERROR(webservice(C13),"SIN CONEXION") -> SIN CONEXION | F13: =IFERROR(MID(E13,SEARCH(""""&D13&""":",E13)+LEN(D13)+3,32),"n/d") -> n/d | G13: =IFERROR(VALUE(SUBSTITUTE(LEFT(SUBSTITUTE(SUBSTITUTE(F13,"""",""),"[",""),MIN(IFERROR(SEARCH(",",SUBSTITUTE(SUBSTITUTE(F13,"""",""),"[","")),99),IFERROR(SEARCH("}",SUBSTITUTE(SUBSTITUTE(F13,"""",""),"[","")),99),IFERROR(SEARCH("]",SUBSTITUTE(SUBSTITUTE(F13,"""",""),"[","")),99))-1),".",MID(1/2,2,1))),"n/d") -> n/d | H13: USD | I13: Referencia institucional EEUU. Prima vs Binance = flujo local.
A14: ETH spot (Coinbase) | B14: Coinbase | C14: https://api.coinbase.com/v2/prices/ETH-USD/spot | D14: amount | E14: =IFERROR(webservice(C14),"SIN CONEXION") -> SIN CONEXION | F14: =IFERROR(MID(E14,SEARCH(""""&D14&""":",E14)+LEN(D14)+3,32),"n/d") -> n/d | G14: =IFERROR(VALUE(SUBSTITUTE(LEFT(SUBSTITUTE(SUBSTITUTE(F14,"""",""),"[",""),MIN(IFERROR(SEARCH(",",SUBSTITUTE(SUBSTITUTE(F14,"""",""),"[","")),99),IFERROR(SEARCH("}",SUBSTITUTE(SUBSTITUTE(F14,"""",""),"[","")),99),IFERROR(SEARCH("]",SUBSTITUTE(SUBSTITUTE(F14,"""",""),"[","")),99))-1),".",MID(1/2,2,1))),"n/d") -> n/d | H14: USD | I14: Idem para ETH.
A15: BTC spot (Kraken) | B15: Kraken | C15: https://api.kraken.com/0/public/Ticker?pair=XBTUSD | D15: c | E15: =IFERROR(webservice(C15),"SIN CONEXION") -> SIN CONEXION | F15: =IFERROR(MID(E15,SEARCH(""""&D15&""":",E15)+LEN(D15)+3,32),"n/d") -> n/d | G15: =IFERROR(VALUE(SUBSTITUTE(LEFT(SUBSTITUTE(SUBSTITUTE(F15,"""",""),"[",""),MIN(IFERROR(SEARCH(",",SUBSTITUTE(SUBSTITUTE(F15,"""",""),"[","")),99),IFERROR(SEARCH("}",SUBSTITUTE(SUBSTITUTE(F15,"""",""),"[","")),99),IFERROR(SEARCH("]",SUBSTITUTE(SUBSTITUTE(F15,"""",""),"[","")),99))-1),".",MID(1/2,2,1))),"n/d") -> n/d | H15: USD | I15: Tercera referencia. Clave 'c' = ultimo cierre.
A16: BTC indice (Deribit) | B16: Deribit | C16: https://www.deribit.com/api/v2/public/get_index_price?index_name=btc_usd | D16: index_price | E16: =IFERROR(webservice(C16),"SIN CONEXION") -> SIN CONEXION | F16: =IFERROR(MID(E16,SEARCH(""""&D16&""":",E16)+LEN(D16)+3,32),"n/d") -> n/d | G16: =IFERROR(VALUE(SUBSTITUTE(LEFT(SUBSTITUTE(SUBSTITUTE(F16,"""",""),"[",""),MIN(IFERROR(SEARCH(",",SUBSTITUTE(SUBSTITUTE(F16,"""",""),"[","")),99),IFERROR(SEARCH("}",SUBSTITUTE(SUBSTITUTE(F16,"""",""),"[","")),99),IFERROR(SEARCH("]",SUBSTITUTE(SUBSTITUTE(F16,"""",""),"[","")),99))-1),".",MID(1/2,2,1))),"n/d") -> n/d | H16: USD | I16: Indice de liquidacion de opciones. El que decide el max pain.
... A20: BTC spot (Bitstamp) | B20: Bitstamp | C20: https://www.bitstamp.net/api/v2/ticker/btcusd/ | D20: last | E20: =IFERROR(webservice(C20),"SIN CONEXION") -> SIN CONEXION | F20: =IFERROR(MID(E20,SEARCH(""""&D20&""":",E20)+LEN(D20)+3,32),"n/d") -> n/d | G20: =IFERROR(VALUE(SUBSTITUTE(LEFT(SUBSTITUTE(SUBSTITUTE(F20,"""",""),"[",""),MIN(IFERROR(SEARCH(",",SUBSTITUTE(SUBSTITUTE(F20,"""",""),"[","")),99),IFERROR(SEARCH("}",SUBSTITUTE(SUBSTITUTE(F20,"""",""),"[","")),99),IFERROR(SEARCH("]",SUBSTITUTE(SUBSTITUTE(F20,"""",""),"[","")),99))-1),".",MID(1/2,2,1))),"n/d") -> n/d | H20: USD | I20: Referencia citada en el analisis del 28-ago (minimo 78,442).

Sheet 3_Live_Derivados
A1: DERIVADOS EN VIVO — FUNDING, OPEN INTEREST, POSICIONAMIENTO
A2: El corazon del modelo. Aqui se ve el combustible de liquidacion antes de que se queme.
A3: La columna E llama a la API. La F aisla el fragmento. La G convierte a numero. Si ves SIN CONEXION, habilita el acceso a datos externos o usa Power Query (hoja 9).
A4: Indicador | B4: Fuente | C4: URL del endpoint (publico, sin clave) | D4: Clave JSON | E4: Respuesta cruda (WEBSERVICE) | F4: Fragmento aislado | G4: VALOR | H4: Unidad | I4: Como se usa en el modelo
A5: Funding BTC (actual) | B5: Binance F. | C5: https://fapi.binance.com/fapi/v1/premiumIndex?symbol=BTCUSDT | D5: lastFundingRate | E5: =IFERROR(webservice(C5),"SIN CONEXION") -> SIN CONEXION | F5: =IFERROR(MID(E5,SEARCH(""""&D5&""":",E5)+LEN(D5)+3,32),"n/d") -> n/d | G5: =IFERROR(VALUE(SUBSTITUTE(LEFT(SUBSTITUTE(SUBSTITUTE(F5,"""",""),"[",""),MIN(IFERROR(SEARCH(",",SUBSTITUTE(SUBSTITUTE(F5,"""",""),"[","")),99),IFERROR(SEARCH("}",SUBSTITUTE(SUBSTITUTE(F5,"""",""),"[","")),99),IFERROR(SEARCH("]",SUBSTITUTE(SUBSTITUTE(F5,"""",""),"[","")),99))-1),".",MID(1/2,2,1))),"n/d") -> n/d | H5: frac/8h | I5: FILTRO 4. Neutro o negativo = setup limpio. >0.0003 = sobrecalentado.
A6: Funding ETH (actual) | B6: Binance F. | C6: https://fapi.binance.com/fapi/v1/premiumIndex?symbol=ETHUSDT | D6: lastFundingRate | E6: =IFERROR(webservice(C6),"SIN CONEXION") -> SIN CONEXION | F6: =IFERROR(MID(E6,SEARCH(""""&D6&""":",E6)+LEN(D6)+3,32),"n/d") -> n/d | G6: =IFERROR(VALUE(SUBSTITUTE(LEFT(SUBSTITUTE(SUBSTITUTE(F6,"""",""),"[",""),MIN(IFERROR(SEARCH(",",SUBSTITUTE(SUBSTITUTE(F6,"""",""),"[","")),99),IFERROR(SEARCH("}",SUBSTITUTE(SUBSTITUTE(F6,"""",""),"[","")),99),IFERROR(SEARCH("]",SUBSTITUTE(SUBSTITUTE(F6,"""",""),"[","")),99))-1),".",MID(1/2,2,1))),"n/d") -> n/d | H6: frac/8h | I6: Divergencia con BTC senala rotacion.
A7: Open Interest BTC (contratos) | B7: Binance F. | C7: https://fapi.binance.com/fapi/v1/openInterest?symbol=BTCUSDT | D7: openInterest | E7: =IFERROR(webservice(C7),"SIN CONEXION") -> SIN CONEXION | F7: =IFERROR(MID(E7,SEARCH(""""&D7&""":",E7)+LEN(D7)+3,32),"n/d") -> n/d | G7: =IFERROR(VALUE(SUBSTITUTE(LEFT(SUBSTITUTE(SUBSTITUTE(F7,"""",""),"[",""),MIN(IFERROR(SEARCH(",",SUBSTITUTE(SUBSTITUTE(F7,"""",""),"[","")),99),IFERROR(SEARCH("}",SUBSTITUTE(SUBSTITUTE(F7,"""",""),"[","")),99),IFERROR(SEARCH("]",SUBSTITUTE(SUBSTITUTE(F7,"""",""),"[","")),99))-1),".",MID(1/2,2,1))),"n/d") -> n/d | H7: BTC | I7: Multiplicar por precio = OI en USD. Base del % purgado.
A8: Open Interest ETH (contratos) | B8: Binance F. | C8: https://fapi.binance.com/fapi/v1/openInterest?symbol=ETHUSDT | D8: openInterest | E8: =IFERROR(webservice(C8),"SIN CONEXION") -> SIN CONEXION | F8: =IFERROR(MID(E8,SEARCH(""""&D8&""":",E8)+LEN(D8)+3,32),"n/d") -> n/d | G8: =IFERROR(VALUE(SUBSTITUTE(LEFT(SUBSTITUTE(SUBSTITUTE(F8,"""",""),"[",""),MIN(IFERROR(SEARCH(",",SUBSTITUTE(SUBSTITUTE(F8,"""",""),"[","")),99),IFERROR(SEARCH("}",SUBSTITUTE(SUBSTITUTE(F8,"""",""),"[","")),99),IFERROR(SEARCH("]",SUBSTITUTE(SUBSTITUTE(F8,"""",""),"[","")),99))-1),".",MID(1/2,2,1))),"n/d") -> n/d | H8: ETH | I8: Idem ETH.
A9: L/S cuentas BTC (retail) | B9: Binance F. | C9: https://fapi.binance.com/futures/data/globalLongShortAccountRatio?symbol=BTCUSDT&period=1h&limit=1 | D9: longShortRatio | E9: =IFERROR(webservice(C9),"SIN CONEXION") -> SIN CONEXION | F9: =IFERROR(MID(E9,SEARCH(""""&D9&""":",E9)+LEN(D9)+3,32),"n/d") -> n/d | G9: =IFERROR(VALUE(SUBSTITUTE(LEFT(SUBSTITUTE(SUBSTITUTE(F9,"""",""),"[",""),MIN(IFERROR(SEARCH(",",SUBSTITUTE(SUBSTITUTE(F9,"""",""),"[","")),99),IFERROR(SEARCH("}",SUBSTITUTE(SUBSTITUTE(F9,"""",""),"[","")),99),IFERROR(SEARCH("]",SUBSTITUTE(SUBSTITUTE(F9,"""",""),"[","")),99))-1),".",MID(1/2,2,1))),"n/d") -> n/d | H9: ratio | I9: La multitud. 70.3% largo el 28-ago. >2 = combustible bajista.
A10: L/S posiciones top BTC (pro) | B10: Binance F. | C10: https://fapi.binance.com/futures/data/topLongShortPositionRatio?symbol=BTCUSDT&period=1h&limit=1 | D10: longShortRatio | E10: =IFERROR(webservice(C10),"SIN CONEXION") -> SIN CONEXION | F10: =IFERROR(MID(E10,SEARCH(""""&D10&""":",E10)+LEN(D10)+3,32),"n/d") -> n/d | G10: =IFERROR(VALUE(SUBSTITUTE(LEFT(SUBSTITUTE(SUBSTITUTE(F10,"""",""),"[",""),MIN(IFERROR(SEARCH(",",SUBSTITUTE(SUBSTITUTE(F10,"""",""),"[","")),99),IFERROR(SEARCH("}",SUBSTITUTE(SUBSTITUTE(F10,"""",""),"[","")),99),IFERROR(SEARCH("]",SUBSTITUTE(SUBSTITUTE(F10,"""",""),"[","")),99))-1),".",MID(1/2,2,1))),"n/d") -> n/d | H10: ratio | I10: El dinero inteligente. 57.4% largo. La BRECHA es la senal.
A11: L/S cuentas ETH | B11: Binance F. | C11: https://fapi.binance.com/futures/data/globalLongShortAccountRatio?symbol=ETHUSDT&period=1h&limit=1 | D11: longShortRatio | E11: =IFERROR(webservice(C11),"SIN CONEXION") -> SIN CONEXION | F11: =IFERROR(MID(E11,SEARCH(""""&D11&""":",E11)+LEN(D11)+3,32),"n/d") -> n/d | G11: =IFERROR(VALUE(SUBSTITUTE(LEFT(SUBSTITUTE(SUBSTITUTE(F11,"""",""),"[",""),MIN(IFERROR(SEARCH(",",SUBSTITUTE(SUBSTITUTE(F11,"""",""),"[","")),99),IFERROR(SEARCH("}",SUBSTITUTE(SUBSTITUTE(F11,"""",""),"[","")),99),IFERROR(SEARCH("]",SUBSTITUTE(SUBSTITUTE(F11,"""",""),"[","")),99))-1),".",MID(1/2,2,1))),"n/d") -> n/d | H11: ratio | I11: ETH tiene beta de liquidacion >2x.
A12: L/S posiciones top ETH | B12: Binance F. | C12: https://fapi.binance.com/futures/data/topLongShortPositionRatio?symbol=ETHUSDT&period=1h&limit=1 | D12: longShortRatio | E12: =IFERROR(webservice(C12),"SIN CONEXION") -> SIN CONEXION | F12: =IFERROR(MID(E12,SEARCH(""""&D12&""":",E12)+LEN(D12)+3,32),"n/d") -> n/d | G12: =IFERROR(VALUE(SUBSTITUTE(LEFT(SUBSTITUTE(SUBSTITUTE(F12,"""",""),"[",""),MIN(IFERROR(SEARCH(",",SUBSTITUTE(SUBSTITUTE(F12,"""",""),"[","")),99),IFERROR(SEARCH("}",SUBSTITUTE(SUBSTITUTE(F12,"""",""),"[","")),99),IFERROR(SEARCH("]",SUBSTITUTE(SUBSTITUTE(F12,"""",""),"[","")),99))-1),".",MID(1/2,2,1))),"n/d") -> n/d | H12: ratio | I12: Idem ETH.
A13: Taker buy/sell BTC | B13: Binance F. | C13: https://fapi.binance.com/futures/data/takerlongshortRatio?symbol=BTCUSDT&period=1h&limit=1 | D13: buySellRatio | E13: =IFERROR(webservice(C13),"SIN CONEXION") -> SIN CONEXION | F13: =IFERROR(MID(E13,SEARCH(""""&D13&""":",E13)+LEN(D13)+3,32),"n/d") -> n/d | G13: =IFERROR(VALUE(SUBSTITUTE(LEFT(SUBSTITUTE(SUBSTITUTE(F13,"""",""),"[",""),MIN(IFERROR(SEARCH(",",SUBSTITUTE(SUBSTITUTE(F13,"""",""),"[","")),99),IFERROR(SEARCH("}",SUBSTITUTE(SUBSTITUTE(F13,"""",""),"[","")),99),IFERROR(SEARCH("]",SUBSTITUTE(SUBSTITUTE(F13,"""",""),"[","")),99))-1),".",MID(1/2,2,1))),"n/d") -> n/d | H13: ratio | I13: Agresion real. <0.9 sostenido en la caida = venta informada, NO comprar.
A14: OI historico BTC (5m) | B14: Binance F. | C14: https://fapi.binance.com/futures/data/openInterestHist?symbol=BTCUSDT&period=5m&limit=1 | D14: sumOpenInterestValue | E14: =IFERROR(webservice(C14),"SIN CONEXION") -> SIN CONEXION | F14: =IFERROR(MID(E14,SEARCH(""""&D14&""":",E14)+LEN(D14)+3,32),"n/d") -> n/d | G14: =IFERROR(VALUE(SUBSTITUTE(LEFT(SUBSTITUTE(SUBSTITUTE(F14,"""",""),"[",""),MIN(IFERROR(SEARCH(",",SUBSTITUTE(SUBSTITUTE(F14,"""",""),"[","")),99),IFERROR(SEARCH("}",SUBSTITUTE(SUBSTITUTE(F14,"""",""),"[","")),99),IFERROR(SEARCH("]",SUBSTITUTE(SUBSTITUTE(F14,"""",""),"[","")),99))-1),".",MID(1/2,2,1))),"n/d") -> n/d | H14: USD | I14: OI en USD directo. Compara contra el valor de hace 1h para medir la purga.
A15: Funding BTC (OKX) | B15: OKX | C15: https://www.okx.com/api/v5/public/funding-rate?instId=BTC-USDT-SWAP | D15: fundingRate | E15: =IFERROR(webservice(C15),"SIN CONEXION") -> SIN CONEXION | F15: =IFERROR(MID(E15,SEARCH(""""&D15&""":",E15)+LEN(D15)+3,32),"n/d") -> n/d | G15: =IFERROR(VALUE(SUBSTITUTE(LEFT(SUBSTITUTE(SUBSTITUTE(F15,"""",""),"[",""),MIN(IFERROR(SEARCH(",",SUBSTITUTE(SUBSTITUTE(F15,"""",""),"[","")),99),IFERROR(SEARCH("}",SUBSTITUTE(SUBSTITUTE(F15,"""",""),"[","")),99),IFERROR(SEARCH("]",SUBSTITUTE(SUBSTITUTE(F15,"""",""),"[","")),99))-1),".",MID(1/2,2,1))),"n/d") -> n/d | H15: frac/8h | I15: Segunda venue. Divergencia entre venues = arbitraje de base.
A16: Ticker BTC perp (Bybit) | B16: Bybit | C16: https://api.bybit.com/v5/market/tickers?category=linear&symbol=BTCUSDT | D16: fundingRate | E16: =IFERROR(webservice(C16),"SIN CONEXION") -> SIN CONEXION | F16: =IFERROR(MID(E16,SEARCH(""""&D16&""":",E16)+LEN(D16)+3,32),"n/d") -> n/d | G16: =IFERROR(VALUE(SUBSTITUTE(LEFT(SUBSTITUTE(SUBSTITUTE(F16,"""",""),"[",""),MIN(IFERROR(SEARCH(",",SUBSTITUTE(SUBSTITUTE(F16,"""",""),"[","")),99),IFERROR(SEARCH("}",SUBSTITUTE(SUBSTITUTE(F16,"""",""),"[","")),99),IFERROR(SEARCH("]",SUBSTITUTE(SUBSTITUTE(F16,"""",""),"[","")),99))-1),".",MID(1/2,2,1))),"n/d") -> n/d | H16: frac/8h | I16: Tercera venue.
... A21: Interes abierto futuros Deribit | B21: Deribit | C21: https://www.deribit.com/api/v2/public/get_book_summary_by_currency?currency=BTC&kind=future | D21: open_interest | E21: =IFERROR(webservice(C21),"SIN CONEXION") -> SIN CONEXION | F21: =IFERROR(MID(E21,SEARCH(""""&D21&""":",E21)+LEN(D21)+3,32),"n/d") -> n/d | G21: =IFERROR(VALUE(SUBSTITUTE(LEFT(SUBSTITUTE(SUBSTITUTE(F21,"""",""),"[",""),MIN(IFERROR(SEARCH(",",SUBSTITUTE(SUBSTITUTE(F21,"""",""),"[","")),99),IFERROR(SEARCH("}",SUBSTITUTE(SUBSTITUTE(F21,"""",""),"[","")),99),IFERROR(SEARCH("]",SUBSTITUTE(SUBSTITUTE(F21,"""",""),"[","")),99))-1),".",MID(1/2,2,1))),"n/d") -> n/d | H21: USD | I21: OI de futuros Deribit.

Sheet 4_Live_Macro
A1: MACRO, SENTIMIENTO Y FLUJOS — APIs PUBLICAS
A2: El bloque que decide si la venta es FORZADA (rebota) o INFORMADA (no rebota). Warsh cambio este bloque el 28-ago.
A3: La columna E llama a la API. La F aisla el fragmento. La G convierte a numero. Si ves SIN CONEXION, habilita el acceso a datos externos o usa Power Query (hoja 9).
A4: Indicador | B4: Fuente | C4: URL del endpoint (publico, sin clave) | D4: Clave JSON | E4: Respuesta cruda (WEBSERVICE) | F4: Fragmento aislado | G4: VALOR | H4: Unidad | I4: Como se usa en el modelo
A5: Fear & Greed cripto | B5: alternative.me | C5: https://api.alternative.me/fng/?limit=1 | D5: value | E5: =IFERROR(webservice(C5),"SIN CONEXION") -> SIN CONEXION | F5: =IFERROR(MID(E5,SEARCH(""""&D5&""":",E5)+LEN(D5)+3,32),"n/d") -> n/d | G5: =IFERROR(VALUE(SUBSTITUTE(LEFT(SUBSTITUTE(SUBSTITUTE(F5,"""",""),"[",""),MIN(IFERROR(SEARCH(",",SUBSTITUTE(SUBSTITUTE(F5,"""",""),"[","")),99),IFERROR(SEARCH("}",SUBSTITUTE(SUBSTITUTE(F5,"""",""),"[","")),99),IFERROR(SEARCH("]",SUBSTITUTE(SUBSTITUTE(F5,"""",""),"[","")),99))-1),".",MID(1/2,2,1))),"n/d") -> n/d | H5: 0-100 | I5: Sentimiento. En el squeeze del 20-ago estuvo en 54 neutro: rally forzado, no euforico.
A6: Fear & Greed (ayer) | B6: alternative.me | C6: https://api.alternative.me/fng/?limit=2 | D6: value | E6: =IFERROR(webservice(C6),"SIN CONEXION") -> SIN CONEXION | F6: =IFERROR(MID(E6,SEARCH(""""&D6&""":",E6)+LEN(D6)+3,32),"n/d") -> n/d | G6: =IFERROR(VALUE(SUBSTITUTE(LEFT(SUBSTITUTE(SUBSTITUTE(F6,"""",""),"[",""),MIN(IFERROR(SEARCH(",",SUBSTITUTE(SUBSTITUTE(F6,"""",""),"[","")),99),IFERROR(SEARCH("}",SUBSTITUTE(SUBSTITUTE(F6,"""",""),"[","")),99),IFERROR(SEARCH("]",SUBSTITUTE(SUBSTITUTE(F6,"""",""),"[","")),99))-1),".",MID(1/2,2,1))),"n/d") -> n/d | H6: 0-100 | I6: Comparar contra hoy para ver la velocidad del cambio de sentimiento.
A7: Cap. total mercado cripto | B7: CoinGecko | C7: https://api.coingecko.com/api/v3/global | D7: active_cryptocurrencies | E7: =IFERROR(webservice(C7),"SIN CONEXION") -> SIN CONEXION | F7: =IFERROR(MID(E7,SEARCH(""""&D7&""":",E7)+LEN(D7)+3,32),"n/d") -> n/d | G7: =IFERROR(VALUE(SUBSTITUTE(LEFT(SUBSTITUTE(SUBSTITUTE(F7,"""",""),"[",""),MIN(IFERROR(SEARCH(",",SUBSTITUTE(SUBSTITUTE(F7,"""",""),"[","")),99),IFERROR(SEARCH("}",SUBSTITUTE(SUBSTITUTE(F7,"""",""),"[","")),99),IFERROR(SEARCH("]",SUBSTITUTE(SUBSTITUTE(F7,"""",""),"[","")),99))-1),".",MID(1/2,2,1))),"n/d") -> n/d | H7: n | I7: Sustituye la clave por 'total_market_cap' con Power Query para el valor real (~2.7T).
A8: BTC vs oro (proxy) | B8: CoinGecko | C8: https://api.coingecko.com/api/v3/simple/price?ids=bitcoin&vs_currencies=xau | D8: xau | E8: =IFERROR(webservice(C8),"SIN CONEXION") -> SIN CONEXION | F8: =IFERROR(MID(E8,SEARCH(""""&D8&""":",E8)+LEN(D8)+3,32),"n/d") -> n/d | G8: =IFERROR(VALUE(SUBSTITUTE(LEFT(SUBSTITUTE(SUBSTITUTE(F8,"""",""),"[",""),MIN(IFERROR(SEARCH(",",SUBSTITUTE(SUBSTITUTE(F8,"""",""),"[","")),99),IFERROR(SEARCH("}",SUBSTITUTE(SUBSTITUTE(F8,"""",""),"[","")),99),IFERROR(SEARCH("]",SUBSTITUTE(SUBSTITUTE(F8,"""",""),"[","")),99))-1),".",MID(1/2,2,1))),"n/d") -> n/d | H8: oz | I8: El 28-ago oro y plata perdieron valor tras Warsh. Ratio BTC/oro = apetito de riesgo real.
A9: DXY proxy (EUR/USD) | B9: Frankfurter/BCE | C9: https://api.frankfurter.app/latest?from=USD&to=EUR | D9: EUR | E9: =IFERROR(webservice(C9),"SIN CONEXION") -> SIN CONEXION | F9: =IFERROR(MID(E9,SEARCH(""""&D9&""":",E9)+LEN(D9)+3,32),"n/d") -> n/d | G9: =IFERROR(VALUE(SUBSTITUTE(LEFT(SUBSTITUTE(SUBSTITUTE(F9,"""",""),"[",""),MIN(IFERROR(SEARCH(",",SUBSTITUTE(SUBSTITUTE(F9,"""",""),"[","")),99),IFERROR(SEARCH("}",SUBSTITUTE(SUBSTITUTE(F9,"""",""),"[","")),99),IFERROR(SEARCH("]",SUBSTITUTE(SUBSTITUTE(F9,"""",""),"[","")),99))-1),".",MID(1/2,2,1))),"n/d") -> n/d | H9: ratio | I9: Sube = dolar fuerte = presion sobre cripto. DXY estaba en 99.5 el 28-ago.
A10: USD/JPY | B10: Frankfurter/BCE | C10: https://api.frankfurter.app/latest?from=USD&to=JPY | D10: JPY | E10: =IFERROR(webservice(C10),"SIN CONEXION") -> SIN CONEXION | F10: =IFERROR(MID(E10,SEARCH(""""&D10&""":",E10)+LEN(D10)+3,32),"n/d") -> n/d | G10: =IFERROR(VALUE(SUBSTITUTE(LEFT(SUBSTITUTE(SUBSTITUTE(F10,"""",""),"[",""),MIN(IFERROR(SEARCH(",",SUBSTITUTE(SUBSTITUTE(F10,"""",""),"[","")),99),IFERROR(SEARCH("}",SUBSTITUTE(SUBSTITUTE(F10,"""",""),"[","")),99),IFERROR(SEARCH("]",SUBSTITUTE(SUBSTITUTE(F10,"""",""),"[","")),99))-1),".",MID(1/2,2,1))),"n/d") -> n/d | H10: ratio | I10: Proxy de carry trade. Rupturas aqui preceden liquidaciones cripto.
A11: Rend. Tesoro 2A | B11: Tesoro EEUU | C11: https://home.treasury.gov/resource-center/data-chart-center/interest-rates/daily-treasury-rates.csv/2026/all?type=daily_treasury_yield_curve&field_tdr_date_value=2026 | D11: 2 Yr | E11: =IFERROR(webservice(C11),"SIN CONEXION") -> SIN CONEXION | F11: =IFERROR(MID(E11,SEARCH(""""&D11&""":",E11)+LEN(D11)+3,32),"n/d") -> n/d | G11: =IFERROR(VALUE(SUBSTITUTE(LEFT(SUBSTITUTE(SUBSTITUTE(F11,"""",""),"[",""),MIN(IFERROR(SEARCH(",",SUBSTITUTE(SUBSTITUTE(F11,"""",""),"[","")),99),IFERROR(SEARCH("}",SUBSTITUTE(SUBSTITUTE(F11,"""",""),"[","")),99),IFERROR(SEARCH("]",SUBSTITUTE(SUBSTITUTE(F11,"""",""),"[","")),99))-1),".",MID(1/2,2,1))),"n/d") -> n/d | H11: % | I11: CSV: usar Power Query (hoja 9). 28-ago: +12pb a 4.35%, maximo de un mes.
A12: Rend. Tesoro 30A | B12: Tesoro EEUU | C12: https://home.treasury.gov/resource-center/data-chart-center/interest-rates/daily-treasury-rates.csv/2026/all?type=daily_treasury_yield_curve&field_tdr_date_value=2026 | D12: 30 Yr | E12: =IFERROR(webservice(C12),"SIN CONEXION") -> SIN CONEXION | F12: =IFERROR(MID(E12,SEARCH(""""&D12&""":",E12)+LEN(D12)+3,32),"n/d") -> n/d | G12: =IFERROR(VALUE(SUBSTITUTE(LEFT(SUBSTITUTE(SUBSTITUTE(F12,"""",""),"[",""),MIN(IFERROR(SEARCH(",",SUBSTITUTE(SUBSTITUTE(F12,"""",""),"[","")),99),IFERROR(SEARCH("}",SUBSTITUTE(SUBSTITUTE(F12,"""",""),"[","")),99),IFERROR(SEARCH("]",SUBSTITUTE(SUBSTITUTE(F12,"""",""),"[","")),99))-1),".",MID(1/2,2,1))),"n/d") -> n/d | H12: % | I12: 28-ago: 5.15%. La parte larga BAJO mientras la corta SUBIO: aplanamiento hawkish.
A13: Fed Funds efectiva (FRED) | B13: FRED | C13: https://fred.stlouisfed.org/graph/fredgraph.csv?id=DFF | D13: DFF | E13: =IFERROR(webservice(C13),"SIN CONEXION") -> SIN CONEXION | F13: =IFERROR(MID(E13,SEARCH(""""&D13&""":",E13)+LEN(D13)+3,32),"n/d") -> n/d | G13: =IFERROR(VALUE(SUBSTITUTE(LEFT(SUBSTITUTE(SUBSTITUTE(F13,"""",""),"[",""),MIN(IFERROR(SEARCH(",",SUBSTITUTE(SUBSTITUTE(F13,"""",""),"[","")),99),IFERROR(SEARCH("}",SUBSTITUTE(SUBSTITUTE(F13,"""",""),"[","")),99),IFERROR(SEARCH("]",SUBSTITUTE(SUBSTITUTE(F13,"""",""),"[","")),99))-1),".",MID(1/2,2,1))),"n/d") -> n/d | H13: % | I13: CSV sin clave. Rango objetivo 3.50-3.75% desde julio.
A14: PCE subyacente (FRED) | B14: FRED | C14: https://fred.stlouisfed.org/graph/fredgraph.csv?id=PCEPILFE | D14: PCEPILFE | E14: =IFERROR(webservice(C14),"SIN CONEXION") -> SIN CONEXION | F14: =IFERROR(MID(E14,SEARCH(""""&D14&""":",E14)+LEN(D14)+3,32),"n/d") -> n/d | G14: =IFERROR(VALUE(SUBSTITUTE(LEFT(SUBSTITUTE(SUBSTITUTE(F14,"""",""),"[",""),MIN(IFERROR(SEARCH(",",SUBSTITUTE(SUBSTITUTE(F14,"""",""),"[","")),99),IFERROR(SEARCH("}",SUBSTITUTE(SUBSTITUTE(F14,"""",""),"[","")),99),IFERROR(SEARCH("]",SUBSTITUTE(SUBSTITUTE(F14,"""",""),"[","")),99))-1),".",MID(1/2,2,1))),"n/d") -> n/d | H14: indice | I14: Warsh cito PCE 12m en 3.7% y 6m en 4.1%. Objetivo firme del 2%.
A15: Flujos ETF BTC spot | B15: Farside | C15: https://farside.co.uk/bitcoin-etf-flow-all-data/ | D15: flow | E15: =IFERROR(webservice(C15),"SIN CONEXION") -> SIN CONEXION | F15: =IFERROR(MID(E15,SEARCH(""""&D15&""":",E15)+LEN(D15)+3,32),"n/d") -> n/d | G15: =IFERROR(VALUE(SUBSTITUTE(LEFT(SUBSTITUTE(SUBSTITUTE(F15,"""",""),"[",""),MIN(IFERROR(SEARCH(",",SUBSTITUTE(SUBSTITUTE(F15,"""",""),"[","")),99),IFERROR(SEARCH("}",SUBSTITUTE(SUBSTITUTE(F15,"""",""),"[","")),99),IFERROR(SEARCH("]",SUBSTITUTE(SUBSTITUTE(F15,"""",""),"[","")),99))-1),".",MID(1/2,2,1))),"n/d") -> n/d | H15: M USD | I15: FILTRO 5. Tabla HTML: usar Power Query. 8 sesiones positivas al 28-ago; 1.92B semanal.
A16: Flujos ETF ETH spot | B16: Farside | C16: https://farside.co.uk/ethereum-etf-flow-all-data/ | D16: flow | E16: =IFERROR(webservice(C16),"SIN CONEXION") -> SIN CONEXION | F16: =IFERROR(MID(E16,SEARCH(""""&D16&""":",E16)+LEN(D16)+3,32),"n/d") -> n/d | G16: =IFERROR(VALUE(SUBSTITUTE(LEFT(SUBSTITUTE(SUBSTITUTE(F16,"""",""),"[",""),MIN(IFERROR(SEARCH(",",SUBSTITUTE(SUBSTITUTE(F16,"""",""),"[","")),99),IFERROR(SEARCH("}",SUBSTITUTE(SUBSTITUTE(F16,"""",""),"[","")),99),IFERROR(SEARCH("]",SUBSTITUTE(SUBSTITUTE(F16,"""",""),"[","")),99))-1),".",MID(1/2,2,1))),"n/d") -> n/d | H16: M USD | I16: 697M semanales en la semana del squeeze.
... A21: Precio BTC fin de mes | B21: Polymarket | C21: https://gamma-api.polymarket.com/markets?closed=false&limit=5 | D21: bestBid | E21: =IFERROR(webservice(C21),"SIN CONEXION") -> SIN CONEXION | F21: =IFERROR(MID(E21,SEARCH(""""&D21&""":",E21)+LEN(D21)+3,32),"n/d") -> n/d | G21: =IFERROR(VALUE(SUBSTITUTE(LEFT(SUBSTITUTE(SUBSTITUTE(F21,"""",""),"[",""),MIN(IFERROR(SEARCH(",",SUBSTITUTE(SUBSTITUTE(F21,"""",""),"[","")),99),IFERROR(SEARCH("}",SUBSTITUTE(SUBSTITUTE(F21,"""",""),"[","")),99),IFERROR(SEARCH("]",SUBSTITUTE(SUBSTITUTE(F21,"""",""),"[","")),99))-1),".",MID(1/2,2,1))),"n/d") -> n/d | H21: prob | I21: Distribucion implicita del mercado de prediccion.

Sheet 5_Liquidaciones
A1: MOTOR FORENSE DE LIQUIDACIONES
A2: Coinglass no ofrece endpoint gratuito sin clave: las celdas amarillas se llenan a mano desde coinglass.com/liquidations (30 segundos). Todo lo demas se calcula solo.
A4: A. ENTRADAS (amarillo = escribir a mano) / VERDE = calculado
A5: Variable | C5: Valor | D5: Unidad | E5: Umbral | F5: Estado | G5: Referencia 28-ago-2026 | H5: Nota
A6: Liquidaciones totales 24h | C6: 487680000 | D6: USD | E6: — | F6: — | G6: 487.68 M | H6: Coinglass / CryptoSlate 28-ago-2026
A7: Liquidaciones ultima 1 hora | C7: 0 | D7: USD | E7: 800000000 | F7: =IF(C7>=E7,"OK","BAJO") -> BAJO | G7: — | H7: FILTRO 1 del dashboard. Es el gatillo real de entrada.
A8: Traders liquidados 24h | C8: 97691 | D8: n | E8: — | F8: — | G8: 97,691 | H8: Para calcular perdida media por cuenta.
A9: Longs liquidados 24h | C9: 360000000 | D9: USD | E9: — | F9: — | G9: 360 M | H9: FILTRO 3 usa la dominancia derivada de aqui.
A10: Shorts liquidados 24h | C10: 127680000 | D10: USD | E10: — | F10: — | G10: 127.68 M | H10: Complemento.
A11: Open Interest agregado (USD) | C11: 56480000000 | D11: USD | E11: — | F11: — | G11: 56.48 B | H11: Denominador del % purgado.
A12: Flujos ETF positivos hoy (1/0) | C12: 1 | D12: 0/1 | E12: 1 | F12: =IF(C12>=E12,"OK","BAJO") -> OK | G12: 1 (8 sesiones) | H12: FILTRO 5. Escribe 1 si los flujos ETF del dia son positivos, 0 si no.
A13: B. METRICAS DERIVADAS — EL ANALISIS QUE NADIE HACE
A14: Metrica derivada | C14: Valor | D14: Formato | E14: Umbral critico | F14: Diagnostico | G14: Valor del 28-ago | H14: Interpretacion
A15: Perdida media por trader | C15: =IFERROR(C6/C8,0) -> 4992.0668 | D15: #,##0 | E15: — | F15: — | G15: ≈ 4,992 USD | H15: Perfil retail apalancado medio-alto, no ballenas.
A16: Dominancia de longs | C16: =IFERROR(C9/C6,0) -> 0.73818898 | D16: 0.0% | E16: 0.75 | F16: =IF(C16>=E16,"CUMPLE","NO CUMPLE") -> NO CUMPLE | G16: 74% | H16: FILTRO 3. >75% confirma purga unilateral.
A17: % del OI purgado (24h) | C17: =IFERROR(C6/C11,0) -> 0.0086345609 | D17: 0.00% | E17: 0.025 | F17: =IF(C17>=E17,"CUMPLE","NO CUMPLE") -> NO CUMPLE | G17: 0.86% | H17: FILTRO 2. HALLAZGO CLAVE: <1% = purga incompleta, queda combustible.
A18: Ratio purga vs capitulacion | C18: =IFERROR((C6/C11)/0.04,0) -> 0.21586402 | D18: 0.00x | E18: 1 | F18: =IF(C18>=E18,"CUMPLE","NO CUMPLE") -> NO CUMPLE | G18: 0.22x | H18: 1.00x = purga de capitulacion (4% del OI). Hoy solo el 22% del camino.
A19: Rebote esperado (ley de escala) | C19: =IFERROR(IF(C6<500000000,0.014,IF(C6<1500000000,0.0275,IF(C6<3000000000,0.0475,0.09))),0) -> 0.014 | D19: 0.00% | E19: — | F19: — | G19: 1.4% | H19: Media del tramo. El rebote escala con la LIQUIDACION, no con la caida.
A20: Rebote real observado hoy (ola 3) | C20: =IFERROR((77712-76909)/76909,0) -> 0.010440911 | D20: 0.00% | E20: — | F20: — | G20: 1.04% | H20: 76,909 -> 77,712. Coincide con la prediccion del modelo.
A21: Error del modelo | C21: =IFERROR(C20-C19,0) -> -0.0035590893 | D21: +0.00%;-0.00% | E21: — | F21: — | G21: -0.36pp | H21: Calibracion. Si el error crece, recalibra los tramos.
A22: Grado de la cascada (0-6) | C22: =(IF(C7>=800000000,1,0))+(IF(C6/C11>=0.025,1.5,0))+(IF(C9/C6>=0.8,1,0))+(IF('1_Dashboard'!E8<=0.0001,1,0))+(IF(C12>0,0.5,0))+(IF(C6>=1000000000,1,0)) -> 1.5 | D22: 0.0 | E22: 4 | F22: =IF(C22>=E22,"CUMPLE","NO CUMPLE") -> NO CUMPLE | G22: 1.5 de 6 | H22: CALIDAD BAJA. Rubrica ponderada (el informe usaba una sin pesos: 2.5/6). Debajo de 4 no se opera.
A24: C. LEY DE ESCALA DEL REBOTE (calibrada con datos observados)
A25: Tramo de liquidacion 24h | C25: Rebote esperado | D25: Con 3x | E25: Con 5x | F25: Con 10x | G25: Evento de referencia | H25: Comentario
A26: < 500 M USD | C26: 0.014 | D26: =C26*3 -> 0.042 | E26: =C26*5 -> 0.07 | F26: =C26*10 -> 0.14 | G26: 28-ago-2026: 487.68 M -> rebote real 1.04% | H26: El apalancamiento multiplica el rebote Y la ruina. Ver hoja 7.
A27: 500 M – 1.5 B | C27: 0.0275 | D27: =C27*3 -> 0.0825 | E27: =C27*5 -> 0.1375 | F27: =C27*10 -> 0.275 | G27: 19-ago-2026: 691.06 M (mayor liq. de cortos desde 2019 en Glassnode) | H27: El apalancamiento multiplica el rebote Y la ruina. Ver hoja 7.
A28: 1.5 B – 3.0 B | C28: 0.0475 | D28: =C28*3 -> 0.1425 | E28: =C28*5 -> 0.2375 | F28: =C28*10 -> 0.475 | G28: Flash crash XRP: 1.35 B en 24h | H28: El apalancamiento multiplica el rebote Y la ruina. Ver hoja 7.
A29: > 3.0 B | C29: 0.09 | D29: =C29*3 -> 0.27 | E29: =C29*5 -> 0.45 | F29: =C29*10 -> 0.9 | G29: Semana del 20-ago: 7.2 B en cortos | H29: El apalancamiento multiplica el rebote Y la ruina. Ver hoja 7.
A31: D. CAMBIO DE POLARIDAD — EL DATO QUE DECIDE EL REGIMEN
A32: Ventana | C32: Liquidaciones | D32: Split dominante | E32: % dominante | F32: Regimen | G32: Fuente | H32: Lectura
A33: 19-ago-2026 | C33: 691060000 | D33: CORTOS | E33: 0.85 | F33: Short squeeze historico | G33: Glassnode / CoinStats | H33: =IF(D33="LONGS","Bajista: el lado concurrido se esta rompiendo","Alcista: cobertura forzada") -> Alcista: cobertura forzada
A34: Semana del 20-ago | C34: 7200000000 | D34: CORTOS | E34: 0.9 | F34: Squeeze en cadena | G34: Trading Economics | H34: =IF(D34="LONGS","Bajista: el lado concurrido se esta rompiendo","Alcista: cobertura forzada") -> Alcista: cobertura forzada
A35: Desde el miercoles 26-ago | C35: 6400000000 | D35: CORTOS | E35: 0.9 | F35: Continuacion | G35: Charles Schwab | H35: =IF(D35="LONGS","Bajista: el lado concurrido se esta rompiendo","Alcista: cobertura forzada") -> Alcista: cobertura forzada
A36: 24h PREVIAS a Warsh | C36: 160470000 | D36: CORTOS | E36: 1 | F36: Ultimo aliento alcista | G36: CoinStats 27-ago | H36: =IF(D36="LONGS","Bajista: el lado concurrido se esta rompiendo","Alcista: cobertura forzada") -> Alcista: cobertura forzada
A37: 24h POSTERIORES a Warsh | C37: 487680000 | D37: LONGS | E37: 0.74 | F37: INVERSION DE REGIMEN | G37: CryptoSlate 28-ago | H37: =IF(D37="LONGS","Bajista: el lado concurrido se esta rompiendo","Alcista: cobertura forzada") -> Bajista: el lado concurrido se esta rompiendo
A38: CONCLUSION DEL MOTOR | C38: =IF(C17<0.025,"PURGA INCOMPLETA - queda combustible de longs abajo - NO comprar la primera cascada","PURGA COMPLETA - el suelo es defendible") -> PURGA INCOMPLETA - queda combustible de longs abajo - NO comprar la primera cascada

Sheet 13_Mapa_Liq
A1: MAPA DE LIQUIDACIONES ESTIMADO — construido desde OI, flujo agresor y apalancamiento
A2: Metodo tipo heatmap: cada aumento de OI se reparte en niveles de apalancamiento y se proyecta su precio de liquidacion. Los niveles ya tocados por el precio se eliminan. Es una ESTIMACION, no el libro real de posiciones.
A4: A. PARAMETROS (amarillo = editable)
A5: Precio de referencia (ultimo cierre) | B5: =IF(COUNT('12_Datos_5m'!$F$5:$F$504)=0,'1_Dashboard'!E6,INDEX('12_Datos_5m'!$F$5:$F$504,COUNT('12_Datos_5m'!$F$5:$F$504))) -> 77477 | D5: Automatico. Si no hay datos 5m usa el precio EN USO del dashboard.
A6: Margen de mantenimiento (MMR) | B6: 0.004 | D6: Binance BTCUSDT tramo base: 0.40%. Acerca el precio de liquidacion.
A7: Vida media de las posiciones (horas) | B7: 24 | D7: Decaimiento: una posicion abierta hace 24h pesa 37% (e^-1). Supuesto.
A8: Ancho de cada franja de precio | B8: 0.005 | D8: 0.5% por fila. 61 filas = +/-15% alrededor del precio.
A9: Ventana para la asimetria | B9: 0.05 | D9: Compara combustible dentro de +/-5%.
A10: Umbral de cluster relevante | B10: 0.25 | D10: Una franja cuenta como cluster si tiene >=25% del maximo.
A11: Ventana de combustible inmediato | B11: 0.02 | D11: Longs a liquidar en el primer 2% de caida.
A13: B. DISTRIBUCION DE APALANCAMIENTO (supuesto editable)
A14: Tramo | B14: Apalanc. | C14: Peso | D14: Liq. long a | E14: Liq. short a | J14: Comentario
A15: Tramo 1 | B15: 5 | C15: 0.15 | D15: =-(1/B15-$B$6) -> -0.196 | E15: =1/B15-$B$6 -> 0.196 | J15: Swing / fondos. Liquidacion lejana.
A16: Tramo 2 | B16: 10 | C16: 0.3 | D16: =-(1/B16-$B$6) -> -0.096 | E16: =1/B16-$B$6 -> 0.096 | J16: El grueso del retail prudente.
A17: Tramo 3 | B17: 25 | C17: 0.3 | D17: =-(1/B17-$B$6) -> -0.036 | E17: =1/B17-$B$6 -> 0.036 | J17: Retail agresivo. Aqui nacen las cascadas.
A18: Tramo 4 | B18: 50 | C18: 0.15 | D18: =-(1/B18-$B$6) -> -0.016 | E18: =1/B18-$B$6 -> 0.016 | J18: Scalpers. Liquidacion a ~1.6%.
A19: Tramo 5 | B19: 100 | C19: 0.1 | D19: =-(1/B19-$B$6) -> -0.006 | E19: =1/B19-$B$6 -> 0.006 | J19: Apuesta pura. Se barre con cualquier mecha.
A20: Suma de pesos (debe ser 100%) | C20: =SUM(C15:C19) -> 1 | D20: =IF(ABS(C20-1)<0.001,"OK","CORRIGE LOS PESOS") -> OK
A22: C. RESUMEN DEL MAPA
A23: Longs vivos a liquidar dentro de -ventana | B23: =SUMIFS($G$44:$G$104,$F$44:$F$104,">="&-$B$9,$F$44:$F$104,"<=0") -> 0 | D23: Combustible bajista: ventas forzadas si el precio cae.
A24: Shorts vivos a liquidar dentro de +ventana | B24: =SUMIFS($H$44:$H$104,$F$44:$F$104,"<="&$B$9,$F$44:$F$104,">=0") -> 0 | D24: Combustible alcista: compras forzadas si el precio sube.
A25: Asimetria (longs / shorts) | B25: =IF(B24=0,IF(B23=0,"n/d",99),B23/B24) -> n/d | D25: El 28-ago en ETH era 7.8x hacia abajo.
A26: Iman de liquidez | B26: =IF(NOT(ISNUMBER(B25)),"SIN DATOS",IF(B25>1.5,"IMAN BAJISTA",IF(B25<0.67,"IMAN ALCISTA","EQUILIBRADO"))) -> SIN DATOS | D26: Hacia donde tiene mas razones mecanicas para ir el precio.
A27: Cluster LONG mayor: precio | B27: =IF(MAX($G$44:$G$104)=0,"n/d",INDEX($C$44:$C$104,MATCH(MAX($G$44:$G$104),$G$44:$G$104,0))) -> n/d | D27: La bolsa de longs mas grande del mapa.
A28: Cluster LONG mayor: tamano | B28: =MAX($G$44:$G$104) -> 0
A29: Cluster SHORT mayor: precio | B29: =IF(MAX($H$44:$H$104)=0,"n/d",INDEX($C$44:$C$104,MATCH(MAX($H$44:$H$104),$H$44:$H$104,0))) -> n/d | D29: La bolsa de shorts mas grande del mapa.
A30: Cluster SHORT mayor: tamano | B30: =MAX($H$44:$H$104) -> 0
A31: Primer cluster LONG relevante: franja | B31: =IF(MAX($G$44:$G$104)=0,"n/d",_xlfn.MAXIFS($B$44:$B$104,$B$44:$B$104,"<=0",$G$44:$G$104,">="&$B$10*MAX($G$44:$G$104))) -> n/d | D31: Indice de franja (auxiliar).
A32: Primer cluster LONG relevante: precio | B32: =IF(ISNUMBER(B31),$B$5*(1+B31*$B$8),"n/d") -> n/d | D32: EL NIVEL A VIGILAR: la primera parada de una cascada.
A33: Primer cluster LONG relevante: distancia | B33: =IF(ISNUMBER(B32),B32/$B$5-1,"n/d") -> n/d
A34: Primer cluster SHORT relevante: franja | B34: =IF(MAX($H$44:$H$104)=0,"n/d",_xlfn.MINIFS($B$44:$B$104,$B$44:$B$104,">=0",$H$44:$H$104,">="&$B$10*MAX($H$44:$H$104))) -> n/d | D34: Indice de franja (auxiliar).
A35: Primer cluster SHORT relevante: precio | B35: =IF(ISNUMBER(B34),$B$5*(1+B34*$B$8),"n/d") -> n/d | D35: La primera parada de un squeeze.
A36: Primer cluster SHORT relevante: distancia | B36: =IF(ISNUMBER(B35),B35/$B$5-1,"n/d") -> n/d
A37: Combustible inmediato (longs en -2%) | B37: =SUMIFS($G$44:$G$104,$F$44:$F$104,">="&-$B$11,$F$44:$F$104,"<=0") -> 0 | D37: Lo que se venderia a mercado en el primer tramo de caida.
A38: Ratio combustible / volumen medio 5m | B38: =IF(COUNT('12_Datos_5m'!$G$5:$G$504)=0,"n/d",B37/AVERAGE('12_Datos_5m'!$G$5:$G$504)) -> n/d | D38: >3x: la cascada se autoalimenta. <1x: el mercado la absorbe.
A39: Liquidaciones YA ejecutadas (estimadas): longs | B39: =SUM('14_Motor_Liq'!$AH$5:$AH$504) -> 0 | D39: Cota superior. Contrasta con la hoja 15 (liquidaciones reales).
A40: Liquidaciones YA ejecutadas (estimadas): shorts | B40: =SUM('14_Motor_Liq'!$AI$5:$AI$504) -> 0
A41: LECTURA DEL MAPA | B41: =IF(B26="SIN DATOS","Instala qBase5m para activar el mapa",B26&" | primer cluster long en "&IF(ISNUMBER(B32),ROUND(B32,0)&" ("&ROUND(B33*100,1)&"%)","n/d")&" | primer cluster short en "&IF(ISNUMBER(B35),ROUND(B35,0)&" (+"&ROUND(B36*100,1)&"%)","n/d")&IF(AND(ISNUMBER(B38),N(B38)>3)," | CASCADA AUTOALIMENTABLE","")) -> Instala qBase5m para activar el mapa
A42: D. MAPA — franjas de 0.5% (arriba = shorts por liquidar / abajo = longs por liquidar)
A43: Etiqueta | B43: Franja | C43: Precio centro | D43: Desde | E43: Hasta | F43: Distancia | G43: LONGS a liquidar | H43: SHORTS a liquidar | I43: Total | J43: Intensidad | K43: Acumulado
...

Sheet 15_Liq_Reales
A1: LIQUIDACIONES REALES — OKX (REST publico) + Binance (colector en tiempo real)
A2: Datos de ordenes de liquidacion ejecutadas, no estimaciones. Cobertura parcial del mercado: se extrapola con el factor de cobertura.
M3: OKX (qLiqOKX -> M4) | T3: BINANCE (qLiqBinanceCSV -> T4)
A4: A. PARAMETROS | M4: ts | N4: Hora | O4: Liquidado | P4: Precio | Q4: BTC | R4: USD | T4: ts | U4: Hora | V4: Liquidado | W4: Precio | X4: BTC | Y4: USD
A5: Factor de cobertura (Binance+OKX / mercado) | B5: 0.5 | E5: SUPUESTO. Ademas Binance solo emite 1 liquidacion/segundo/simbolo: subestima en cascadas.
A6: Ruta del CSV del colector | B6: C:\trading\liquidaciones_binance.csv | E6: Nombre definido RutaCSV. La lee la consulta qLiqBinanceCSV.
A7: Tu diferencia horaria con UTC (horas) | B7: -4 | E7: Bolivia = -4. Se usa para calcular 'ahora' en UTC.
A8: Ahora en UTC (ms) | B8: =ROUND((NOW()-DATE(1970,1,1)-B7/24)*86400000,0) -> 1790012128845 | E8: Ventanas de 1h/4h/24h medidas contra este instante.
A10: B. METRICAS DE LIQUIDACION REAL
A11: Metrica | B11: OKX | C11: Binance | D11: MERCADO (estimado) | E11: Lectura
A12: Longs liquidados 1h | B12: =SUMIFS($R$5:$R$5004,$O$5:$O$5004,"LONG",$M$5:$M$5004,">="&($B$8-1*3600000)) -> 0 | C12: =SUMIFS($Y$5:$Y$50004,$V$5:$V$50004,"LONG",$T$5:$T$50004,">="&($B$8-1*3600000)) -> 0 | D12: =(B12+C12)/$B$5 -> 0 | E12: FILTRO 1 (junto con shorts).
A13: Shorts liquidados 1h | B13: =SUMIFS($R$5:$R$5004,$O$5:$O$5004,"SHORT",$M$5:$M$5004,">="&($B$8-1*3600000)) -> 0 | C13: =SUMIFS($Y$5:$Y$50004,$V$5:$V$50004,"SHORT",$T$5:$T$50004,">="&($B$8-1*3600000)) -> 0 | D13: =(B13+C13)/$B$5 -> 0
A14: Longs liquidados 4h | B14: =SUMIFS($R$5:$R$5004,$O$5:$O$5004,"LONG",$M$5:$M$5004,">="&($B$8-4*3600000)) -> 0 | C14: =SUMIFS($Y$5:$Y$50004,$V$5:$V$50004,"LONG",$T$5:$T$50004,">="&($B$8-4*3600000)) -> 0 | D14: =(B14+C14)/$B$5 -> 0
A15: Shorts liquidados 4h | B15: =SUMIFS($R$5:$R$5004,$O$5:$O$5004,"SHORT",$M$5:$M$5004,">="&($B$8-4*3600000)) -> 0 | C15: =SUMIFS($Y$5:$Y$50004,$V$5:$V$50004,"SHORT",$T$5:$T$50004,">="&($B$8-4*3600000)) -> 0 | D15: =(B15+C15)/$B$5 -> 0
A16: Longs liquidados 24h | B16: =SUMIFS($R$5:$R$5004,$O$5:$O$5004,"LONG",$M$5:$M$5004,">="&($B$8-24*3600000)) -> 0 | C16: =SUMIFS($Y$5:$Y$50004,$V$5:$V$50004,"LONG",$T$5:$T$50004,">="&($B$8-24*3600000)) -> 0 | D16: =(B16+C16)/$B$5 -> 0 | E16: Comparable al dato de Coinglass.
A17: Shorts liquidados 24h | B17: =SUMIFS($R$5:$R$5004,$O$5:$O$5004,"SHORT",$M$5:$M$5004,">="&($B$8-24*3600000)) -> 0 | C17: =SUMIFS($Y$5:$Y$50004,$V$5:$V$50004,"SHORT",$T$5:$T$50004,">="&($B$8-24*3600000)) -> 0 | D17: =(B17+C17)/$B$5 -> 0
A18: Dominancia de longs 1h | B18: =IF(B12+B13=0,"n/d",B12/(B12+B13)) -> n/d | C18: =IF(C12+C13=0,"n/d",C12/(C12+C13)) -> n/d | D18: =IF(D12+D13=0,"n/d",D12/(D12+D13)) -> n/d | E18: FILTRO 3. >75% = purga unilateral.
A19: Eventos de liquidacion 1h | B19: =COUNTIFS($M$5:$M$5004,">="&($B$8-3600000)) -> 0 | C19: =COUNTIFS($T$5:$T$50004,">="&($B$8-3600000)) -> 0 | D19: =(B19+C19)/$B$5 -> 0 | E19: Muchos eventos pequenos = retail.
A20: Mayor liquidacion individual 24h | B20: =_xlfn.MAXIFS($R$5:$R$5004,$M$5:$M$5004,">="&($B$8-86400000)) -> 0 | C20: =_xlfn.MAXIFS($Y$5:$Y$50004,$T$5:$T$50004,">="&($B$8-86400000)) -> 0 | D20: =MAX(B20,C20) -> 0 | E20: Una sola > 5M = ballena liquidada.
A21: Precio medio de liquidacion LONG 1h | B21: =IF(B12=0,"n/d",SUMPRODUCT(($O$5:$O$5004="LONG")*($M$5:$M$5004>=$B$8-3600000)*$P$5:$P$5004*$R$5:$R$5004)/B12) -> n/d | C21: =IF(C12=0,"n/d",SUMPRODUCT(($V$5:$V$50004="LONG")*($T$5:$T$50004>=$B$8-3600000)*$W$5:$W$50004*$Y$5:$Y$50004)/C12) -> n/d | D21: =IFERROR((N(B21)*B12+N(C21)*C12)/(B12+C12),"n/d") -> n/d | E21: Donde se disparo la cascada: suele volverse soporte.
A22: Precio medio de liquidacion SHORT 1h | B22: =IF(B13=0,"n/d",SUMPRODUCT(($O$5:$O$5004="SHORT")*($M$5:$M$5004>=$B$8-3600000)*$P$5:$P$5004*$R$5:$R$5004)/B13) -> n/d | C22: =IF(C13=0,"n/d",SUMPRODUCT(($V$5:$V$50004="SHORT")*($T$5:$T$50004>=$B$8-3600000)*$W$5:$W$50004*$Y$5:$Y$50004)/C13) -> n/d | D22: =IFERROR((N(B22)*B13+N(C22)*C13)/(B13+C13),"n/d") -> n/d | E22: Donde se disparo el squeeze: suele volverse resistencia.
A24: C. DETECTOR DE CASCADA — ultimas 2 horas en bloques de 5 min (ambas fuentes)
A25: Bloque (minutos atras) | B25: Longs | C25: Shorts | D25: Total | E25: Senal
A26: -120 a -115 min | B26: =SUMIFS($R$5:$R$5004,$O$5:$O$5004,"LONG",$M$5:$M$5004,">="&($B$8-120*60000),$M$5:$M$5004,"<"&($B$8-115*60000))+SUMIFS($Y$5:$Y$50004,$V$5:$V$50004,"LONG",$T$5:$T$50004,">="&($B$8-120*60000),$T$5:$T$50004,"<"&($B$8-115*60000)) -> 0 | C26: =SUMIFS($R$5:$R$5004,$O$5:$O$5004,"SHORT",$M$5:$M$5004,">="&($B$8-120*60000),$M$5:$M$5004,"<"&($B$8-115*60000))+SUMIFS($Y$5:$Y$50004,$V$5:$V$50004,"SHORT",$T$5:$T$50004,">="&($B$8-120*60000),$T$5:$T$50004,"<"&($B$8-115*60000)) -> 0 | D26: =B26+C26 -> 0 | E26: =IF(AND(D26>0,D26>=3*MAX($B$51,1)),IF(B26>C26,"<< CASCADA LONG","<< SQUEEZE SHORT"),"")
A27: -115 a -110 min | B27: =SUMIFS($R$5:$R$5004,$O$5:$O$5004,"LONG",$M$5:$M$5004,">="&($B$8-115*60000),$M$5:$M$5004,"<"&($B$8-110*60000))+SUMIFS($Y$5:$Y$50004,$V$5:$V$50004,"LONG",$T$5:$T$50004,">="&($B$8-115*60000),$T$5:$T$50004,"<"&($B$8-110*60000)) -> 0 | C27: =SUMIFS($R$5:$R$5004,$O$5:$O$5004,"SHORT",$M$5:$M$5004,">="&($B$8-115*60000),$M$5:$M$5004,"<"&($B$8-110*60000))+SUMIFS($Y$5:$Y$50004,$V$5:$V$50004,"SHORT",$T$5:$T$50004,">="&($B$8-115*60000),$T$5:$T$50004,"<"&($B$8-110*60000)) -> 0 | D27: =B27+C27 -> 0 | E27: =IF(AND(D27>0,D27>=3*MAX($B$51,1)),IF(B27>C27,"<< CASCADA LONG","<< SQUEEZE SHORT"),"")
A28: -110 a -105 min | B28: =SUMIFS($R$5:$R$5004,$O$5:$O$5004,"LONG",$M$5:$M$5004,">="&($B$8-110*60000),$M$5:$M$5004,"<"&($B$8-105*60000))+SUMIFS($Y$5:$Y$50004,$V$5:$V$50004,"LONG",$T$5:$T$50004,">="&($B$8-110*60000),$T$5:$T$50004,"<"&($B$8-105*60000)) -> 0 | C28: =SUMIFS($R$5:$R$5004,$O$5:$O$5004,"SHORT",$M$5:$M$5004,">="&($B$8-110*60000),$M$5:$M$5004,"<"&($B$8-105*60000))+SUMIFS($Y$5:$Y$50004,$V$5:$V$50004,"SHORT",$T$5:$T$50004,">="&($B$8-110*60000),$T$5:$T$50004,"<"&($B$8-105*60000)) -> 0 | D28: =B28+C28 -> 0 | E28: =IF(AND(D28>0,D28>=3*MAX($B$51,1)),IF(B28>C28,"<< CASCADA LONG","<< SQUEEZE SHORT"),"")
A29: -105 a -100 min | B29: =SUMIFS($R$5:$R$5004,$O$5:$O$5004,"LONG",$M$5:$M$5004,">="&($B$8-105*60000),$M$5:$M$5004,"<"&($B$8-100*60000))+SUMIFS($Y$5:$Y$50004,$V$5:$V$50004,"LONG",$T$5:$T$50004,">="&($B$8-105*60000),$T$5:$T$50004,"<"&($B$8-100*60000)) -> 0 | C29: =SUMIFS($R$5:$R$5004,$O$5:$O$5004,"SHORT",$M$5:$M$5004,">="&($B$8-105*60000),$M$5:$M$5004,"<"&($B$8-100*60000))+SUMIFS($Y$5:$Y$50004,$V$5:$V$50004,"SHORT",$T$5:$T$50004,">="&($B$8-105*60000),$T$5:$T$50004,"<"&($B$8-100*60000)) -> 0 | D29: =B29+C29 -> 0 | E29: =IF(AND(D29>0,D29>=3*MAX($B$51,1)),IF(B29>C29,"<< CASCADA LONG","<< SQUEEZE SHORT"),"")
A30: -100 a -95 min | B30: =SUMIFS($R$5:$R$5004,$O$5:$O$5004,"LONG",$M$5:$M$5004,">="&($B$8-100*60000),$M$5:$M$5004,"<"&($B$8-95*60000))+SUMIFS($Y$5:$Y$50004,$V$5:$V$50004,"LONG",$T$5:$T$50004,">="&($B$8-100*60000),$T$5:$T$50004,"<"&($B$8-95*60000)) -> 0 | C30: =SUMIFS($R$5:$R$5004,$O$5:$O$5004,"SHORT",$M$5:$M$5004,">="&($B$8-100*60000),$M$5:$M$5004,"<"&($B$8-95*60000))+SUMIFS($Y$5:$Y$50004,$V$5:$V$50004,"SHORT",$T$5:$T$50004,">="&($B$8-100*60000),$T$5:$T$50004,"<"&($B$8-95*60000)) -> 0 | D30: =B30+C30 -> 0 | E30: =IF(AND(D30>0,D30>=3*MAX($B$51,1)),IF(B30>C30,"<< CASCADA LONG","<< SQUEEZE SHORT"),"")
A31: -95 a -90 min | B31: =SUMIFS($R$5:$R$5004,$O$5:$O$5004,"LONG",$M$5:$M$5004,">="&($B$8-95*60000),$M$5:$M$5004,"<"&($B$8-90*60000))+SUMIFS($Y$5:$Y$50004,$V$5:$V$50004,"LONG",$T$5:$T$50004,">="&($B$8-95*60000),$T$5:$T$50004,"<"&($B$8-90*60000)) -> 0 | C31: =SUMIFS($R$5:$R$5004,$O$5:$O$5004,"SHORT",$M$5:$M$5004,">="&($B$8-95*60000),$M$5:$M$5004,"<"&($B$8-90*60000))+SUMIFS($Y$5:$Y$50004,$V$5:$V$50004,"SHORT",$T$5:$T$50004,">="&($B$8-95*60000),$T$5:$T$50004,"<"&($B$8-90*60000)) -> 0 | D31: =B31+C31 -> 0 | E31: =IF(AND(D31>0,D31>=3*MAX($B$51,1)),IF(B31>C31,"<< CASCADA LONG","<< SQUEEZE SHORT"),"")
A32: -90 a -85 min | B32: =SUMIFS($R$5:$R$5004,$O$5:$O$5004,"LONG",$M$5:$M$5004,">="&($B$8-90*60000),$M$5:$M$5004,"<"&($B$8-85*60000))+SUMIFS($Y$5:$Y$50004,$V$5:$V$50004,"LONG",$T$5:$T$50004,">="&($B$8-90*60000),$T$5:$T$50004,"<"&($B$8-85*60000)) -> 0 | C32: =SUMIFS($R$5:$R$5004,$O$5:$O$5004,"SHORT",$M$5:$M$5004,">="&($B$8-90*60000),$M$5:$M$5004,"<"&($B$8-85*60000))+SUMIFS($Y$5:$Y$50004,$V$5:$V$50004,"SHORT",$T$5:$T$50004,">="&($B$8-90*60000),$T$5:$T$50004,"<"&($B$8-85*60000)) -> 0 | D32: =B32+C32 -> 0 | E32: =IF(AND(D32>0,D32>=3*MAX($B$51,1)),IF(B32>C32,"<< CASCADA LONG","<< SQUEEZE SHORT"),"")
A33: -85 a -80 min | B33: =SUMIFS($R$5:$R$5004,$O$5:$O$5004,"LONG",$M$5:$M$5004,">="&($B$8-85*60000),$M$5:$M$5004,"<"&($B$8-80*60000))+SUMIFS($Y$5:$Y$50004,$V$5:$V$50004,"LONG",$T$5:$T$50004,">="&($B$8-85*60000),$T$5:$T$50004,"<"&($B$8-80*60000)) -> 0 | C33: =SUMIFS($R$5:$R$5004,$O$5:$O$5004,"SHORT",$M$5:$M$5004,">="&($B$8-85*60000),$M$5:$M$5004,"<"&($B$8-80*60000))+SUMIFS($Y$5:$Y$50004,$V$5:$V$50004,"SHORT",$T$5:$T$50004,">="&($B$8-85*60000),$T$5:$T$50004,"<"&($B$8-80*60000)) -> 0 | D33: =B33+C33 -> 0 | E33: =IF(AND(D33>0,D33>=3*MAX($B$51,1)),IF(B33>C33,"<< CASCADA LONG","<< SQUEEZE SHORT"),"")
A34: -80 a -75 min | B34: =SUMIFS($R$5:$R$5004,$O$5:$O$5004,"LONG",$M$5:$M$5004,">="&($B$8-80*60000),$M$5:$M$5004,"<"&($B$8-75*60000))+SUMIFS($Y$5:$Y$50004,$V$5:$V$50004,"LONG",$T$5:$T$50004,">="&($B$8-80*60000),$T$5:$T$50004,"<"&($B$8-75*60000)) -> 0 | C34: =SUMIFS($R$5:$R$5004,$O$5:$O$5004,"SHORT",$M$5:$M$5004,">="&($B$8-80*60000),$M$5:$M$5004,"<"&($B$8-75*60000))+SUMIFS($Y$5:$Y$50004,$V$5:$V$50004,"SHORT",$T$5:$T$50004,">="&($B$8-80*60000),$T$5:$T$50004,"<"&($B$8-75*60000)) -> 0 | D34: =B34+C34 -> 0 | E34: =IF(AND(D34>0,D34>=3*MAX($B$51,1)),IF(B34>C34,"<< CASCADA LONG","<< SQUEEZE SHORT"),"")
A35: -75 a -70 min | B35: =SUMIFS($R$5:$R$5004,$O$5:$O$5004,"LONG",$M$5:$M$5004,">="&($B$8-75*60000),$M$5:$M$5004,"<"&($B$8-70*60000))+SUMIFS($Y$5:$Y$50004,$V$5:$V$50004,"LONG",$T$5:$T$50004,">="&($B$8-75*60000),$T$5:$T$50004,"<"&($B$8-70*60000)) -> 0 | C35: =SUMIFS($R$5:$R$5004,$O$5:$O$5004,"SHORT",$M$5:$M$5004,">="&($B$8-75*60000),$M$5:$M$5004,"<"&($B$8-70*60000))+SUMIFS($Y$5:$Y$50004,$V$5:$V$50004,"SHORT",$T$5:$T$50004,">="&($B$8-75*60000),$T$5:$T$50004,"<"&($B$8-70*60000)) -> 0 | D35: =B35+C35 -> 0 | E35: =IF(AND(D35>0,D35>=3*MAX($B$51,1)),IF(B35>C35,"<< CASCADA LONG","<< SQUEEZE SHORT"),"")
A36: -70 a -65 min | B36: =SUMIFS($R$5:$R$5004,$O$5:$O$5004,"LONG",$M$5:$M$5004,">="&($B$8-70*60000),$M$5:$M$5004,"<"&($B$8-65*60000))+SUMIFS($Y$5:$Y$50004,$V$5:$V$50004,"LONG",$T$5:$T$50004,">="&($B$8-70*60000),$T$5:$T$50004,"<"&($B$8-65*60000)) -> 0 | C36: =SUMIFS($R$5:$R$5004,$O$5:$O$5004,"SHORT",$M$5:$M$5004,">="&($B$8-70*60000),$M$5:$M$5004,"<"&($B$8-65*60000))+SUMIFS($Y$5:$Y$50004,$V$5:$V$50004,"SHORT",$T$5:$T$50004,">="&($B$8-70*60000),$T$5:$T$50004,"<"&($B$8-65*60000)) -> 0 | D36: =B36+C36 -> 0 | E36: =IF(AND(D36>0,D36>=3*MAX($B$51,1)),IF(B36>C36,"<< CASCADA LONG","<< SQUEEZE SHORT"),"")
